python: can't open file '/workspaces/codespaces-blank/jx/strategy005.py.py': [Errno 2] No such file or directory
Traceback (most recent call last):
  File "/workspaces/codespaces-blank/jx/strategy005.py", line 1, in <module>
    from selenium import webdriver
ModuleNotFoundError: No module named 'selenium'
Traceback (most recent call last):
  File "/workspaces/codespaces-blank/jx/strategy005.py", line 4, in <module>
    driver = webdriver.Firefox()
  File "/usr/local/python/3.10.13/lib/python3.10/site-packages/selenium/webdriver/firefox/webdriver.py", line 69, in __init__
    super().__init__(command_executor=executor, options=options)
  File "/usr/local/python/3.10.13/lib/python3.10/site-packages/selenium/webdriver/remote/webdriver.py", line 208, in __init__
    self.start_session(capabilities)
  File "/usr/local/python/3.10.13/lib/python3.10/site-packages/selenium/webdriver/remote/webdriver.py", line 292, in start_session
    response = self.execute(Command.NEW_SESSION, caps)["value"]
  File "/usr/local/python/3.10.13/lib/python3.10/site-packages/selenium/webdriver/remote/webdriver.py", line 347, in execute
    self.error_handler.check_response(response)
  File "/usr/local/python/3.10.13/lib/python3.10/site-packages/selenium/webdriver/remote/errorhandler.py", line 229, in check_response
    raise exception_class(message, screen, stacktrace)
selenium.common.exceptions.WebDriverException: Message: Process unexpectedly closed with status 1

